Workbook

Sheet Risk Scoring Calculator
A1: ARIE FINANCE LTD — CLIENT RISK SCORING MODEL
A2: AML / CFT Risk Assessment Framework | Based on FATF Risk-Based Approach (Banking Sector)
A4: Client / Entity Name:
A5: Application Reference:
A6: Assessment Date: | B6: 17 March 2026
A7: Assessed By:
A9: RISK FACTOR | B9: SELECTION | C9: SCORE (1–4) | D9: SUB-FACTOR WEIGHT | E9: WEIGHTED SCORE
A10: DIMENSION 1: CUSTOMER / ENTITY RISK | Dimension Weight: 30%
A11: 1.1 Entity Type | C11: =IFERROR(VLOOKUP(B11,'Score Reference'!$A$3:$B$14,2,FALSE()),0) -> 0 | D11: 0.2 | E11: =IF(ISNUMBER(C11),C11*D11,0) -> 0
A12: 1.2 Ownership Structure | C12: =IFERROR(VLOOKUP(B12,'Score Reference'!$A$19:$B$22,2,FALSE()),0) -> 0 | D12: 0.2 | E12: =IF(ISNUMBER(C12),C12*D12,0) -> 0
A13: 1.3 PEP Status | C13: =IFERROR(VLOOKUP(B13,'Score Reference'!$A$27:$B$30,2,FALSE()),0) -> 0 | D13: 0.25 | E13: =IF(ISNUMBER(C13),C13*D13,0) -> 0
A14: 1.4 Adverse Media / Negative News | C14: =IFERROR(VLOOKUP(B14,'Score Reference'!$A$35:$B$37,2,FALSE()),0) -> 0 | D14: 0.15 | E14: =IF(ISNUMBER(C14),C14*D14,0) -> 0
A15: 1.5 Source of Wealth | C15: =IFERROR(VLOOKUP(B15,'Score Reference'!$A$141:$B$148,2,FALSE()),"") | D15: 0.1 | E15: =IF(ISNUMBER(C15),C15*D15,0) -> 0
A16: 1.6 Initial Source of Funds | C16: =IFERROR(VLOOKUP(B16,'Score Reference'!$A$152:$B$160,2,FALSE()),"") | D16: 0.1 | E16: =IF(ISNUMBER(C16),C16*D16,0) -> 0
A17: DIMENSION 1 SCORE | B17: Dimension Score (1–4) | D17: 0.3 | E17: =IFERROR(SUMPRODUCT(C11:C16,D11:D16),0) -> 0
A19: DIMENSION 2: GEOGRAPHIC RISK | Dimension Weight: 25%
A20: 2.1 Country of Incorporation | C20: =IFERROR(VLOOKUP(B20,'Score Reference'!$A$43:$B$46,2,FALSE()),0) -> 0 | D20: 0.25 | E20: =IF(ISNUMBER(C20),C20*D20,0) -> 0
A21: 2.2 UBO Nationalities | C21: =IFERROR(VLOOKUP(B21,'Score Reference'!$A$205:$B$208,2,FALSE()),0) -> 0 | D21: 0.2 | E21: =IF(ISNUMBER(C21),C21*D21,0) -> 0
A22: 2.3 Intermediary Shareholder Jurisdictions | C22: =IFERROR(VLOOKUP(B22,'Score Reference'!$A$213:$B$216,2,FALSE()),0) -> 0 | D22: 0.2 | E22: =IF(ISNUMBER(C22),C22*D22,0) -> 0
A23: 2.4 Countries of Operation | C23: =IFERROR(VLOOKUP(B23,'Score Reference'!$A$51:$B$54,2,FALSE()),0) -> 0 | D23: 0.2 | E23: =IF(ISNUMBER(C23),C23*D23,0) -> 0
A24: 2.5 Target Markets / Payment Corridors | C24: =IFERROR(VLOOKUP(B24,'Score Reference'!$A$59:$B$62,2,FALSE()),0) -> 0 | D24: 0.15 | E24: =IF(ISNUMBER(C24),C24*D24,0) -> 0
A25: DIMENSION 2 SCORE | B25: Dimension Score (1–4) | D25: 0.25 | E25: =IFERROR(SUMPRODUCT(C20:C24,D20:D24),0) -> 0
A27: DIMENSION 3: PRODUCT / SERVICE RISK | Dimension Weight: 20%
A28: 3.1 Primary Service Required | B28: Domestic payments only (single currency) | C28: =IFERROR(VLOOKUP(B28,'Score Reference'!$A$68:$B$70,2,FALSE()),0) -> 1 | D28: 0.4 | E28: =IF(ISNUMBER(C28),C28*D28,0) -> 0.4
A29: 3.2 Expected Monthly Transaction Volume | C29: =IFERROR(VLOOKUP(B29,'Score Reference'!$A$76:$B$79,2,FALSE()),0) -> 0 | D29: 0.35 | E29: =IF(ISNUMBER(C29),C29*D29,0) -> 0
A30: 3.3 Transaction Complexity & Corridors | C30: =IFERROR(VLOOKUP(B30,'Score Reference'!$A$84:$B$87,2,FALSE()),0) -> 0 | D30: 0.25 | E30: =IF(ISNUMBER(C30),C30*D30,0) -> 0
A31: DIMENSION 3 SCORE | B31: Dimension Score (1–4) | D31: 0.2 | E31: =IFERROR(SUMPRODUCT(C28:C30,D28:D30),0) -> 0.4
A33: DIMENSION 4: INDUSTRY / SECTOR RISK | Dimension Weight: 15%
A34: 4.1 Business Sector / Industry | C34: =IFERROR(VLOOKUP(B34,'Score Reference'!$A$93:$B$120,2,FALSE()),0) -> 0 | D34: 1 | E34: =IF(ISNUMBER(C34),C34*D34,0) -> 0
A35: DIMENSION 4 SCORE | B35: Dimension Score (1–4) | D35: 0.15 | E35: =IFERROR(SUMPRODUCT(C34,D34),0) -> 0
A37: DIMENSION 5: DELIVERY CHANNEL RISK | Dimension Weight: 10%
A38: 5.1 Introduction / Referral Method | C38: =IFERROR(VLOOKUP(B38,'Score Reference'!$A$125:$B$128,2,FALSE()),0) -> 0 | D38: 0.5 | E38: =IF(ISNUMBER(C38),C38*D38,0) -> 0
A39: 5.2 Customer Interaction Type | C39: =IFERROR(VLOOKUP(B39,'Score Reference'!$A$133:$B$136,2,FALSE()),0) -> 0 | D39: 0.5 | E39: =IF(ISNUMBER(C39),C39*D39,0) -> 0
A40: DIMENSION 5 SCORE | B40: Dimension Score (1–4) | D40: 0.1 | E40: =IFERROR(SUMPRODUCT(C38:C39,D38:D39),0) -> 0
A48: OVERALL RISK ASSESSMENT
A49: WEIGHTED COMPOSITE SCORE | B49: Normalised score out of 100 | E49: =IFERROR(ROUND((E17+E25+E31+E35+E40)/4*100,1),0) -> 10
A50: RISK RATING | B50: Low (0–39) | Medium (40–69) | High (70–100) | E50: =IF(E49>=70,"HIGH RISK",IF(E49>=40,"MEDIUM RISK",IF(E49>0,"LOW RISK","Awaiting Input"))) -> LOW RISK
A51: DUE DILIGENCE REQUIREMENT | B51: =IF(E49>=70,"Enhanced Due Diligence (EDD) — Senior Compliance Review Required",IF(E49>=40,"Customer Due Diligence (CDD) — Standard Onboarding",IF(E49>0,"Simplified Due Diligence (SDD) — Fast-Track Eligible",""))) -> Simplified Due Diligence (SDD) — Fast-Track Eligible
A52: COMPLIANCE APPROVAL FLAG | B52: =IF(OR(COUNTIF(C11:C16,4)>0,COUNTIF(C20:C24,4)>0,COUNTIF(C28:C30,4)>0,COUNTIF(C34,4)>0,E49>=85),"⚠️ MANDATORY COMPLIANCE OFFICER APPROVAL REQUIRED","")
A54: Source: ARIE Finance Ltd — AML/CFT Risk Scoring Model v1.5 | FATF Risk-Based Approach (Banking Sector) Guidance | Last Updated: March 2026

Sheet Score Reference
A1: ARIE FINANCE LTD — SCORE REFERENCE DATA
A2: 1.1 Entity Type
A3: Listed Company on Regulated Exchange | B3: 1 | C3: Low Risk
A4: Regulated Financial Institution | B4: 1 | C4: Low Risk
A5: Government / Public Sector Entity | B5: 1 | C5: Low Risk
A6: Large Private Company (revenue > USD 10m) | B6: 2 | C6: Medium Risk
A7: SME / Private Company | B7: 2 | C7: Medium Risk
A8: Newly Incorporated Company (< 1 year) | B8: 3 | C8: High Risk
A9: Trust | B9: 3 | C9: High Risk
A10: Foundation | B10: 3 | C10: High Risk
A11: Regulated Fund (CIS / Licensed) | B11: 2 | C11: Medium Risk
A12: Unregulated Fund / SPV | B12: 4 | C12: Very High Risk
A13: Non-Profit Organisation / NGO | B13: 3 | C13: High Risk
A14: Shell Company / Special Purpose Vehicle | B14: 4 | C14: Very High Risk
A18: 1.2 Ownership Structure
A19: Simple — direct identifiable UBOs | B19: 1 | C19: Low Risk
A20: 1–2 ownership layers | B20: 2 | C20: Medium Risk
A21: 3+ ownership layers / nominee shareholders | B21: 3 | C21: High Risk
A22: Complex multi-jurisdiction / opaque structure | B22: 4 | C22: Very High Risk
A26: 1.3 PEP Status
A27: No PEP connection | B27: 1 | C27: Low Risk
A28: Close associate or family member of PEP | B28: 3 | C28: High Risk
A29: Domestic Politically Exposed Person (PEP) | B29: 3 | C29: High Risk
A30: Foreign / International PEP | B30: 4 | C30: Very High Risk
A34: 1.4 Adverse Media / Negative News
A35: No adverse media identified | B35: 1 | C35: Low Risk
A36: Minor or unsubstantiated reports | B36: 2 | C36: Medium Risk
A37: Confirmed adverse media / regulatory action | B37: 4 | C37: Very High Risk
A42: 2.1 Country of Incorporation
A43: FATF member — low risk jurisdiction | B43: 1 | C43: Low Risk
A44: FATF member — standard / emerging jurisdiction | B44: 2 | C44: Medium Risk
A45: FATF Grey List country | B45: 3 | C45: High Risk
A46: FATF Black List / sanctioned country | B46: 4 | C46: Very High Risk
A50: 2.4 Countries of Operation
A51: All low-risk jurisdictions | B51: 1 | C51: Low Risk
A52: Predominantly low-risk with some medium-risk jurisdictions | B52: 2 | C52: Medium Risk
A53: Includes high-risk jurisdictions | B53: 3 | C53: High Risk
A54: Predominantly high-risk or sanctioned jurisdictions | B54: 4 | C54: Very High Risk
A58: 2.5 Target Markets / Payment Corridors
A59: Developed markets only | B59: 1 | C59: Low Risk
...

Sheet Country Risk Reference
A1: ARIE FINANCE LTD — COUNTRY RISK REFERENCE TABLE
A2: COUNTRY | B2: REGION | C2: FATF MEMBER | D2: FATF STATUS | E2: RISK SCORE | F2: RISK CATEGORY | G2: NOTES
A3: Australia | B3: Asia-Pacific | C3: Yes | D3: Clear | E3: 1 | F3: Low Risk | G3: FATF member; strong AML framework
A4: Canada | B4: Americas | C4: Yes | D4: Clear | E4: 1 | F4: Low Risk | G4: FATF member; strong AML framework
A5: France | B5: Europe | C5: Yes | D5: Clear | E5: 1 | F5: Low Risk | G5: FATF founding member
A6: Germany | B6: Europe | C6: Yes | D6: Clear | E6: 1 | F6: Low Risk | G6: FATF founding member
A7: Hong Kong SAR | B7: Asia-Pacific | C7: Yes | D7: Clear | E7: 1 | F7: Low Risk | G7: Strong regulatory framework
A8: Ireland | B8: Europe | C8: Yes | D8: Clear | E8: 1 | F8: Low Risk | G8: EU member; robust AML laws
A9: Japan | B9: Asia-Pacific | C9: Yes | D9: Clear | E9: 1 | F9: Low Risk | G9: FATF member; strong controls
A10: Luxembourg | B10: Europe | C10: Yes | D10: Clear | E10: 1 | F10: Low Risk | G10: EU financial centre
A11: Netherlands | B11: Europe | C11: Yes | D11: Clear | E11: 1 | F11: Low Risk | G11: FATF founding member
A12: New Zealand | B12: Asia-Pacific | C12: Yes | D12: Clear | E12: 1 | F12: Low Risk | G12: Strong AML/CFT framework
A13: Singapore | B13: Asia-Pacific | C13: Yes | D13: Clear | E13: 1 | F13: Low Risk | G13: MAS-regulated; highly compliant
A14: Switzerland | B14: Europe | C14: Yes | D14: Clear | E14: 1 | F14: Low Risk | G14: Strong FINMA-regulated framework
... A82: Sudan | B82: Africa | C82: No | D82: Black List | E82: 4 | F82: Very High Risk | G82: Conflict; sanctions apply

Sheet AI Verification Checks
A1: ARIE FINANCE LTD — AI DOCUMENT VERIFICATION CHECKS
A2: Automated checks performed on each uploaded document during client onboarding
A4: SECTION A — CORPORATE ENTITY DOCUMENTS
A5: # | B5: Document | C5: Check Name | D5: Verification Rule | E5: Check Type | F5: Client Prompt if Failed
A6: 1 | B6: Certificate of Incorporation | C6: Entity Name Match | D6: Company name on certificate must match the applicant entity name | E6: Name | F6: Client prompted to verify or re-upload
A7: 2 | C7: Registration Number | D7: Registration / incorporation number must be present and legible | E7: Content | F7: Client asked to upload a clearer copy
A8: 3 | C8: Document Clarity | D8: Document must be legible; certified copy if applicable | E8: Quality | F8: Client asked to re-upload a clearer version
A9: 4 | B9: Memorandum & Articles of Association | C9: Entity Name Match | D9: Company name must match the applicant entity | E9: Name | F9: Client prompted to verify
A10: 5 | C10: Completeness | D10: All pages must be present and legible | E10: Quality | F10: Client asked to re-upload full document
A11: 6 | C11: Certification | D11: Must be a certified or signed copy | E11: Quality | F11: Client prompted to upload certified version
A12: 7 | B12: Certificate of Registration | C12: Entity Name Match | D12: Company name must match | E12: Name | F12: Client prompted to verify
A13: 8 | C13: Current Validity | D13: Must be current and not expired | E13: Expiry | F13: Client prompted: document is expired, upload valid version
A14: 9 | C14: Document Clarity | D14: Must be legible and complete | E14: Quality | F14: Client asked to re-upload a clearer copy
A15: 10 | B15: Shareholder Register | C15: Ownership Consistency | D15: Shareholdings must match UBOs declared in application | E15: Content | F15: Client prompted: ownership does not match declared UBOs
A16: 11 | C16: Completeness | D16: Total ownership must add up to 100% | E16: Content | F16: Client prompted: total does not sum to 100%
A17: 12 | C17: Currency | D17: Register must reflect current shareholding structure | E17: Age (≤12 mo) | F17: Client prompted: document may be outdated
A18: 13 | B18: Register of Directors | C18: Director Consistency | D18: Directors must match those declared in application | E18: Content | F18: Client prompted: directors do not match application
A19: 14 | C19: Completeness | D19: All current directors must be listed | E19: Content | F19: Client prompted: list appears incomplete
A20: 15 | C20: Document Clarity | D20: Must be legible | E20: Quality | F20: Client asked to re-upload a clearer copy
A21: 16 | B21: Latest Annual Financial Statements / Management Accounts | C21: Financial Period | D21: Must be for most recent financial year; forecast if entity < 1 year old | E21: Age (≤18 mo) | F21: Client prompted: statements are too old
A22: 17 | C22: Entity Name Match | D22: Company name on statements must match the applicant | E22: Name | F22: Client prompted to verify entity name
A23: 18 | C23: Audit Status | D23: Preferably audited; management accounts acceptable for new entities | E23: Content | F23: Client informed: unaudited — management accounts noted
A24: 19 | C24: Completeness | D24: Balance sheet, P&L, and notes must be present | E24: Quality | F24: Client prompted: financial statements appear incomplete
A25: 20 | B25: Proof of Registered Address | C25: Document Date | D25: Must be dated within the last 3 months | E25: Age (≤3 mo) | F25: Client prompted: document is older than 3 months
A26: 21 | C26: Entity Name Match | D26: Entity name on document must match the applicant | E26: Name | F26: Client prompted to verify
A27: 22 | C27: Document Clarity | D27: Document must be legible and unredacted | E27: Quality | F27: Client asked to re-upload a clearer copy
A28: 23 | C28: Address Match | D28: Address must match the registered office address on application | E28: Content | F28: Client prompted: address does not match application
A29: 24 | B29: Board Resolution | C29: Signatory Match | D29: Authorised signatory must be a declared director | E29: Name | F29: Client prompted: signatory is not a known director
A30: 25 | C30: Resolution Date | D30: Must be dated and reasonably current | E30: Age (≤12 mo) | F30: Client prompted: resolution may be outdated
A31: 26 | C31: Scope of Authority | D31: Must authorise the signatory to open the account | E31: Content | F31: Client prompted: resolution does not cover account opening
A32: 27 | B32: Company Structure Chart | C32: UBO Chain | D32: Must trace ownership to ultimate beneficial owners | E32: Content | F32: Client prompted: UBO chain is incomplete
A33: 28 | C33: Ownership Match | D33: Shareholdings must match shareholder register | E33: Content | F33: Client prompted: structure does not match register
A34: 29 | C34: Legibility | D34: Diagram must be clear and readable | E34: Quality | F34: Client asked to re-upload a clearer version
A35: 30 | B35: Bank Reference Letter (High / Very High Risk only) | C35: Bank Letterhead | D35: Must be on official bank letterhead | E35: Quality | F35: Client prompted: document does not appear to be on bank letterhead
A36: 31 | C36: Document Date | D36: Must be dated within the last 3 months | E36: Age (≤3 mo) | F36: Client prompted: letter is older than 3 months
A37: 32 | C37: Entity Name Match | D37: Entity name must match the applicant | E37: Name | F37: Client prompted to verify entity name
A38: 33 | B38: Regulatory Licence(s) | C38: Licence Validity | D38: Licence must not be expired | E38: Expiry | F38: Client prompted: licence appears expired
A39: 34 | C39: Entity Name Match | D39: Licensee name must match the applicant entity | E39: Name | F39: Client prompted to verify
A40: 35 | C40: Licence Scope | D40: Licence must cover the activities described in the application | E40: Content | F40: Client prompted: licence scope may not cover declared activities
A42: SECTION B — DIRECTORS & UBO IDENTITY DOCUMENTS
...

Sheet AI Agent Registry
A1: ARIE FINANCE LTD — AI AGENT REGISTRY
A2: AI-assisted compliance pipeline — agent definitions, trigger points, and outputs
A4: ONBOARDING AGENTS (1-5)
A5: # | B5: Agent Name | C5: Purpose | D5: Trigger Point | E5: Key Checks / Inputs | F5: Output | G5: Status
A6: 1 | B6: Identity & Document Integrity Agent | C6: Automatically read, validate, and cross-reference uploaded documents in real time. Performs 66 automated checks across 16 document types. | D6: Each document upload (real-time, immediate feedback) | E6: OCR text extraction & document type identification Expiry / validity detection Date checks (3mo / 6mo / 12mo / 18mo rules) Name matching (entity & person) Document clarity / legibility scoring Cross-document consistency checks Duplicate detection Registry verification Completeness scoring | F6: Per-document: Pass / Warning / Fail with specific client prompts Aggregate: Document completeness score Cross-reference: Name & registry match summary | G6: Live
A7: 2 | B7: Corporate Structure & UBO Mapping Agent | C7: Analyse declared ownership structures, trace beneficial ownership chains, and identify ultimate beneficial owners (UBOs). | D7: After application form submission, during AI risk scoring phase | E7: Ownership chain tracing (direct & indirect) UBO identification (≥25% threshold) Multi-layered entity detection Circular ownership detection Nominee / trust identification Shareholder register cross-reference Structure chart validation PEP/sanctions check on all identified UBOs | F7: Simple Structure → Proceed Complex Structure → Flag for enhanced review Opaque / Circular → Escalate to compliance | G7: Live
A8: 3 | B8: Business Model Plausibility Agent | C8: Evaluate whether the business story is plausible and internally consistent. Compare against industry benchmarks. | D8: During AI risk scoring phase (after application submission) | E8: Business description vs sector alignment Transaction volume vs company size benchmarking Geography vs business model logic Revenue model plausibility Industry norm comparison Payment corridor risk assessment Source of funds vs business activity consistency Source of wealth vs entity profile | F8: Consistent → Proceed Needs Clarification → Flag specific areas Suspicious Profile → Escalate with reasoning | G8: Live
A9: 4 | B9: FinCrime Screening Interpretation Agent | C9: Analyse screening results from sanctions, PEP, and adverse media databases. Consolidate hits, remove false positives. | D9: During AI risk scoring phase | E9: Global sanctions screening (UN, EU, OFAC, HMT) PEP database analysis (World-Check, Dow Jones) Adverse media scanning (100,000+ sources) False positive analysis & reduction Hit severity ranking & categorisation Consolidated risk narrative generation | F9: All Clear → No escalation needed Review Required → True positive identified with context Escalate → Confirmed match (sanctions/PEP) with evidence | G9: Live
A10: 5 | B10: Compliance Memo & Risk Recommendation Agent | C10: Combine all signals from all agents into a structured compliance memo with risk recommendation. AI never approves — only recommends. | D10: End of AI risk scoring phase (after all other agents complete) | E10: 5-dimension weighted composite scoring Jurisdiction risk (Dimension 2) Industry risk (Dimension 4) Ownership complexity (Dimension 1) Screening results integration Document completeness signal Business plausibility assessment Complete compliance memo generation | F10: Risk Score (0-100) + Level (Low/Medium/High/Very High) Decision Routing: LOW/MEDIUM → KYC & Documents stage HIGH/VERY HIGH → Compliance review + notification Full compliance memo with all findings | G10: Live
A11: 6 | B11: Periodic Review Preparation Agent | C11: Track review schedules, identify expired documents, and prepare review packages for compliance officers. | D11: Scheduled (based on risk-level review cycles: annual/biannual/quarterly) | E11: Review cycle tracking by risk level Expired document identification Document renewal deadline monitoring Review package preparation Priority scoring for overdue reviews Client notification triggers | F11: Up to Date → No action needed Review Due → Package prepared for compliance Documents Pending → Client notified to upload Overdue → Escalated to compliance manager | G11: Live
A12: 7 | B12: Adverse Media & PEP Monitoring Agent | C12: Continuous monitoring of adverse media and PEP databases for all active clients. | D12: Ongoing (daily automated scans + event-driven alerts) | E12: New adverse media detection (100,000+ sources) Sanctions list update monitoring (UN, EU, OFAC, HMT) PEP status change detection New directorship / association alerts Severity classification & false positive filtering Historical trend analysis | F12: No Change → Continue monitoring New Alert → Risk change detected with context Escalate → Immediate compliance review required | G12: Live
A13: 8 | B13: Behaviour & Risk Drift Agent | C13: Monitor changes in client activity patterns and risk profile over time. | D13: Ongoing (event-driven + periodic analysis) | E13: Transaction pattern vs declared volumes Geographic activity vs declared corridors New product/service usage detection Counterparty risk changes Volume spike / drop analysis Seasonal pattern deviation | F13: Within Expected → Continue monitoring Drift Detected → Flag for review with analysis Significant Deviation → Escalate with full report | G13: Live
A14: 9 | B14: Regulatory Impact Agent | C14: Monitor regulatory changes across relevant jurisdictions and assess impact on existing client portfolio. | D14: Event-driven (new regulation / guidance published) | E14: Regulatory change detection (FSC, BoM, FATF, EU) Client portfolio impact assessment Jurisdiction-specific rule mapping Licence requirement change monitoring Compliance deadline tracking Gap analysis (current vs new requirements) | F14: No Impact → Log for records Minor Impact → Update client risk profile Significant Impact → Compliance action required with deadline | G14: Future Phase
A15: 10 | B15: Ongoing Compliance Review Agent | C15: Generate periodic compliance review reports consolidating all monitoring signals. | D15: Scheduled (aligned with periodic review cycles) | E15: All monitoring agent signal consolidation Risk score trend analysis Incident history compilation Document status summary Compliance action tracking Recommendation generation for review outcome | F15: Low Risk → Maintain current status Elevated Risk → Enhanced monitoring recommended High Risk → Relationship review / exit consideration | G15: Live
A16: ONGOING MONITORING AGENTS (6-10)
A18: AI COMPLIANCE PIPELINE FLOW
A20: Client Portal | B20: Registration & Login | D20: —
A21: → | B21: Application Form | D21: —
A22: → | B22: AI Risk Scoring | D22: Corporate Structure & UBO Mapping + Business Model Plausibility + FinCrime Screening Interpretation + Compliance Memo & Risk Recommendation
A23: → | B23: Decision Routing | D23: LOW/MEDIUM Risk → KYC & Documents HIGH/VERY HIGH Risk → Compliance Review + Notification
A24: → | B24: KYC Document Upload | D24: Identity & Document Integrity Agent (66 checks)
A25: → | B25: Pre-Submission Review | D25: —
A26: → | B26: Final Submission | D26: Compliance Memo & Risk Recommendation Agent
A27: → | B27: Human Compliance Review | D27: Compliance officer makes final decision
A28: → | B28: Account Activated | D28: Monitoring Agents (6-10) begin lifecycle monitoring
A32: STRATEGIC ADVANTAGE
A33: With this AI-assisted compliance pipeline, ARIE Finance can realistically achieve low-risk onboarding decisions in 24 hours or less — extremely competitive compared to traditional banks and payment institutions. The 5 monitoring agents provide continuous lifecycle risk management post-onboarding.
A35: Total AI Agents: 10 (5 Onboarding + 5 Monitoring) | Total AI Verification Checks: 66 | Document Types Covered: 16

Sheet Methodology
A1: ARIE FINANCE LTD — RISK SCORING MODEL: METHODOLOGY
A2: AML/CFT Risk Assessment Framework — Version 1.5
A4: PURPOSE
A5: This model provides a standardised, repeatable risk assessment framework for all corporate clients applying for Payment Intermediary Services (PIS) through ARIE Finance Ltd. It is designed to comply with the FATF Risk-Based Approach for banking and payment institutions.
A7: REGULATORY BASIS
A8: FATF Recommendations (2012, updated 2023) | FATF Risk-Based Approach Guidance: Banking Sector | FSC Mauritius AML/CFT Guidelines | Bank of Mauritius AML/CFT Guideline (2022)
A10: SCORING SCALE
A11: Each sub-factor is scored on a 1–4 scale: 1 = Low Risk 2 = Medium Risk 3 = High Risk 4 = Very High Risk
A13: DIMENSION WEIGHTS
A14: Dimension 1: Customer / Entity Risk — 30% Dimension 2: Geographic Risk — 25% • 2.1 Country of Incorporation (25%) • 2.2 UBO Nationalities (20%) • 2.3 Intermediary Shareholder Jurisdictions (20%) • 2.4 Countries of Operation (20%) • 2.5 Target Markets / Payment Corridors (15%) Dimension 3: Product / Service Risk — 20% Dimension 4: Industry / Sector Risk — 15% Dimension 5: Delivery Channel Risk — 10% Sub-factors 1.5 (Source of Wealth) and 1.6 (Initial Source of Funds) are included under Dimension 1 as customer-level risk indicators.
A16: COMPOSITE SCORE
A17: The weighted composite score is calculated as: Score = (Sum of all dimension weighted scores ÷ 4) × 100 This produces a normalised score from 0 to 100.
... A35: Version 1.5 — 17 March 2026 Change: Geographic Risk (Dimension 2) expanded from 3 to 5 sub-criteria. Added UBO Nationalities (20%) and Intermediary Shareholder Jurisdictions (20%) as new sub-factors. Rebalanced geographic sub-factor weights: Country of Incorporation 25%, UBO Nationalities 20%, Intermediary Shareholder Jurisdictions 20%, Countries of Operation 20%, Target Markets 15%. Updated VLOOKUP ranges and data validations. Entity types expanded in v1.4 (Trust, Foundation, Regulated Fund, Unregulated Fund/SPV split). Added Management Consulting and Financial/Tax Advisory sectors.
