Workbook

Sheet Change Log
A1: ONBOARDA — RISK SCORING MODEL: PROPOSED CHANGES
A2: Review copy — changes highlighted in yellow (modified), green (added), red (removed)
A4: Change ID | B4: Severity | C4: Sheet | D4: Description | E4: Old Value | F4: New Value
A5: C-01 | B5: CRITICAL | C5: Country Risk Reference | D5: Add BVI (British Virgin Islands) — was missing entirely. Secrecy jurisdiction, must score 4. | E5: Not listed (defaults to 2 in code) | F5: Score 4 — Very High Risk
A6: C-02 | B6: CRITICAL | C6: Country Risk Reference | D6: Add Cayman Islands — was missing entirely. Secrecy jurisdiction, must score 4. | E6: Not listed (defaults to 2 in code) | F6: Score 4 — Very High Risk
A7: C-03 | B7: CRITICAL | C7: Country Risk Reference | D7: Add Panama — was missing entirely. Secrecy jurisdiction, must score 4. | E7: Not listed (defaults to 2 in code) | F7: Score 4 — Very High Risk
A8: C-04 | B8: HIGH | C8: Country Risk Reference | D8: Reclassify Seychelles from score 2 (Medium) to score 3 (High). IFC/FSA regulated but frequently used in opaque structures. | E8: Score 2 — Medium Risk | F8: Score 3 — High Risk
A9: C-05 | B9: HIGH | C9: Country Risk Reference | D9: Reclassify Mauritius from score 2 to score 2 (unchanged but add note). Previously EU-listed. Consider whether score 2 is appropriate given its use in intermediary structures. | E9: Score 2 (no change) | F9: Score 2 (note added)
A10: C-06 | B10: HIGH | C10: Country Risk Reference | D10: Add Bermuda — missing secrecy jurisdiction. Score 3 (regulated but offshore). | E10: Not listed | F10: Score 3 — High Risk
A11: C-07 | B11: HIGH | C11: Country Risk Reference | D11: Add Jersey — missing secrecy jurisdiction. Score 2 (well-regulated Crown Dependency). | E11: Not listed | F11: Score 2 — Medium Risk
A12: C-08 | B12: HIGH | C12: Country Risk Reference | D12: Add Guernsey — missing. Score 2 (well-regulated Crown Dependency). | E12: Not listed | F12: Score 2 — Medium Risk
A13: C-09 | B13: HIGH | C13: Country Risk Reference | D13: Add Isle of Man — missing. Score 2 (Crown Dependency, regulated). | E13: Not listed | F13: Score 2 — Medium Risk
A14: C-10 | B14: HIGH | C14: Country Risk Reference | D14: Add Liechtenstein — missing. Score 2 (EEA member, FATF member). | E14: Not listed | F14: Score 2 — Medium Risk
A15: C-11 | B15: HIGH | C15: Country Risk Reference | D15: Add Vanuatu — missing secrecy jurisdiction. Score 3. | E15: Not listed | F15: Score 3 — High Risk
... A29: C-25 | B29: INFO | C29: Methodology | D29: Update version to v1.6. Document all changes in version control section. | E29: Version 1.5 — 17 March 2026 | F29: Version 1.6 — 26 March 2026

Sheet Risk Scoring Calculator
A1: ARIE FINANCE LTD — CLIENT RISK SCORING MODEL
A2: AML / CFT Risk Assessment Framework | Based on FATF Risk-Based Approach (Banking Sector)
A4: Client / Entity Name:
A5: Application Reference:
A6: Assessment Date: | B6: 17 March 2026
A7: Assessed By:
A9: RISK FACTOR | B9: SELECTION | C9: SCORE (1–4) | D9: SUB-FACTOR WEIGHT | E9: WEIGHTED SCORE
A10: DIMENSION 1: CUSTOMER / ENTITY RISK | Dimension Weight: 30%
A11: 1.1 Entity Type | C11: =IFERROR(VLOOKUP(B11,'Score Reference'!$A$3:$B$14,2,FALSE()),0) -> 0 | D11: 0.2 | E11: =IF(ISNUMBER(C11),C11*D11,0) -> 0
A12: 1.2 Ownership Structure | C12: =IFERROR(VLOOKUP(B12,'Score Reference'!$A$19:$B$22,2,FALSE()),0) -> 0 | D12: 0.2 | E12: =IF(ISNUMBER(C12),C12*D12,0) -> 0
A13: 1.3 PEP Status | C13: =IFERROR(VLOOKUP(B13,'Score Reference'!$A$27:$B$30,2,FALSE()),0) -> 0 | D13: 0.25 | E13: =IF(ISNUMBER(C13),C13*D13,0) -> 0
A14: 1.4 Adverse Media / Negative News | C14: =IFERROR(VLOOKUP(B14,'Score Reference'!$A$35:$B$37,2,FALSE()),0) -> 0 | D14: 0.15 | E14: =IF(ISNUMBER(C14),C14*D14,0) -> 0
A15: 1.5 Source of Wealth | C15: =IFERROR(VLOOKUP(B15,'Score Reference'!$A$141:$B$148,2,FALSE()),"") | D15: 0.1 | E15: =IF(ISNUMBER(C15),C15*D15,0) -> 0
A16: 1.6 Initial Source of Funds | C16: =IFERROR(VLOOKUP(B16,'Score Reference'!$A$152:$B$160,2,FALSE()),"") | D16: 0.1 | E16: =IF(ISNUMBER(C16),C16*D16,0) -> 0
A17: DIMENSION 1 SCORE | B17: Dimension Score (1–4) | D17: 0.3 | E17: =IFERROR(SUMPRODUCT(C11:C16,D11:D16),0) -> 0
A19: DIMENSION 2: GEOGRAPHIC RISK | Dimension Weight: 25%
A20: 2.1 Country of Incorporation | C20: =IFERROR(VLOOKUP(B20,'Score Reference'!$A$43:$B$46,2,FALSE()),0) -> 0 | D20: 0.25 | E20: =IF(ISNUMBER(C20),C20*D20,0) -> 0
A21: 2.2 UBO Nationalities | C21: =IFERROR(VLOOKUP(B21,'Score Reference'!$A$205:$B$208,2,FALSE()),0) -> 0 | D21: 0.2 | E21: =IF(ISNUMBER(C21),C21*D21,0) -> 0
A22: 2.3 Intermediary Shareholder Jurisdictions | C22: =IFERROR(VLOOKUP(B22,'Score Reference'!$A$213:$B$216,2,FALSE()),0) -> 0 | D22: 0.2 | E22: =IF(ISNUMBER(C22),C22*D22,0) -> 0
A23: 2.4 Countries of Operation | C23: =IFERROR(VLOOKUP(B23,'Score Reference'!$A$51:$B$54,2,FALSE()),0) -> 0 | D23: 0.2 | E23: =IF(ISNUMBER(C23),C23*D23,0) -> 0
A24: 2.5 Target Markets / Payment Corridors | C24: =IFERROR(VLOOKUP(B24,'Score Reference'!$A$59:$B$62,2,FALSE()),0) -> 0 | D24: 0.15 | E24: =IF(ISNUMBER(C24),C24*D24,0) -> 0
A25: DIMENSION 2 SCORE | B25: Dimension Score (1–4) | D25: 0.25 | E25: =IFERROR(SUMPRODUCT(C20:C24,D20:D24),0) -> 0
A27: DIMENSION 3: PRODUCT / SERVICE RISK | Dimension Weight: 20%
A28: 3.1 Primary Service Required | B28: Domestic payments only (single currency) | C28: =IFERROR(VLOOKUP(B28,'Score Reference'!$A$68:$B$70,2,FALSE()),0) -> 1 | D28: 0.4 | E28: =IF(ISNUMBER(C28),C28*D28,0) -> 0.4
A29: 3.2 Expected Monthly Transaction Volume | C29: =IFERROR(VLOOKUP(B29,'Score Reference'!$A$76:$B$79,2,FALSE()),0) -> 0 | D29: 0.35 | E29: =IF(ISNUMBER(C29),C29*D29,0) -> 0
A30: 3.3 Transaction Complexity & Corridors | C30: =IFERROR(VLOOKUP(B30,'Score Reference'!$A$84:$B$87,2,FALSE()),0) -> 0 | D30: 0.25 | E30: =IF(ISNUMBER(C30),C30*D30,0) -> 0
A31: DIMENSION 3 SCORE | B31: Dimension Score (1–4) | D31: 0.2 | E31: =IFERROR(SUMPRODUCT(C28:C30,D28:D30),0) -> 0.4
A33: DIMENSION 4: INDUSTRY / SECTOR RISK | Dimension Weight: 15%
A34: 4.1 Business Sector / Industry | C34: =IFERROR(VLOOKUP(B34,'Score Reference'!$A$93:$B$120,2,FALSE()),0) -> 0 | D34: 1 | E34: =IF(ISNUMBER(C34),C34*D34,0) -> 0
A35: DIMENSION 4 SCORE | B35: Dimension Score (1–4) | D35: 0.15 | E35: =IFERROR(SUMPRODUCT(C34,D34),0) -> 0
A37: DIMENSION 5: DELIVERY CHANNEL RISK | Dimension Weight: 10%
A38: 5.1 Introduction / Referral Method | C38: =IFERROR(VLOOKUP(B38,'Score Reference'!$A$125:$B$128,2,FALSE()),0) -> 0 | D38: 0.5 | E38: =IF(ISNUMBER(C38),C38*D38,0) -> 0
A39: 5.2 Customer Interaction Type | C39: =IFERROR(VLOOKUP(B39,'Score Reference'!$A$133:$B$136,2,FALSE()),0) -> 0 | D39: 0.5 | E39: =IF(ISNUMBER(C39),C39*D39,0) -> 0
A40: DIMENSION 5 SCORE | B40: Dimension Score (1–4) | D40: 0.1 | E40: =IFERROR(SUMPRODUCT(C38:C39,D38:D39),0) -> 0
A48: OVERALL RISK ASSESSMENT
A49: WEIGHTED COMPOSITE SCORE | B49: Normalised score out of 100 | E49: =IFERROR(ROUND((E17+E25+E31+E35+E40)/4*100,1),0) -> 10
A50: RISK RATING | B50: Low (0–29) | Medium (30–49) | High (50–69) | Very High (70–100) | E50: =IF(E49>=70,"HIGH RISK",IF(E49>=40,"MEDIUM RISK",IF(E49>0,"LOW RISK","Awaiting Input"))) -> LOW RISK
A51: DUE DILIGENCE REQUIREMENT | B51: =IF(E49>=70,"Enhanced Due Diligence (EDD) — Senior Compliance Review Required",IF(E49>=40,"Customer Due Diligence (CDD) — Standard Onboarding",IF(E49>0,"Simplified Due Diligence (SDD) — Fast-Track Eligible",""))) -> Simplified Due Diligence (SDD) — Fast-Track Eligible
A52: COMPLIANCE APPROVAL FLAG | B52: =IF(OR(COUNTIF(C11:C16,4)>0,COUNTIF(C20:C24,4)>0,COUNTIF(C28:C30,4)>0,COUNTIF(C34,4)>0,E49>=85),"⚠️ MANDATORY COMPLIANCE OFFICER APPROVAL REQUIRED","")
A54: Source: ARIE Finance Ltd — AML/CFT Risk Scoring Model v1.5 | FATF Risk-Based Approach (Banking Sector) Guidance | Last Updated: March 2026

Sheet Score Reference
A1: ARIE FINANCE LTD — SCORE REFERENCE DATA
A2: 1.1 Entity Type
A3: Listed Company on Regulated Exchange | B3: 1 | C3: Low Risk
A4: Regulated Financial Institution | B4: 1 | C4: Low Risk
A5: Government / Public Sector Entity | B5: 1 | C5: Low Risk
A6: Large Private Company (revenue > USD 10m) | B6: 2 | C6: Medium Risk
A7: SME / Private Company | B7: 2 | C7: Medium Risk
A8: Newly Incorporated Company (< 1 year) | B8: 3 | C8: High Risk
A9: Trust | B9: 3 | C9: High Risk
A10: Foundation | B10: 3 | C10: High Risk
A11: Regulated Fund (CIS / Licensed) | B11: 2 | C11: Medium Risk
A12: Unregulated Fund / SPV | B12: 4 | C12: Very High Risk
A13: Non-Profit Organisation / NGO | B13: 3 | C13: High Risk
A14: Shell Company / Special Purpose Vehicle | B14: 4 | C14: Very High Risk
A18: 1.2 Ownership Structure
A19: Simple — direct identifiable UBOs | B19: 1 | C19: Low Risk
A20: 1–2 ownership layers | B20: 2 | C20: Medium Risk
A21: 3+ ownership layers / nominee shareholders | B21: 3 | C21: High Risk
A22: Complex multi-jurisdiction / opaque structure | B22: 4 | C22: Very High Risk
A26: 1.3 PEP Status
A27: No PEP connection | B27: 1 | C27: Low Risk
A28: Close associate or family member of PEP | B28: 3 | C28: High Risk
A29: Domestic Politically Exposed Person (PEP) | B29: 3 | C29: High Risk
A30: Foreign / International PEP | B30: 4 | C30: Very High Risk
A34: 1.4 Adverse Media / Negative News
A35: No adverse media identified | B35: 1 | C35: Low Risk
A36: Minor or unsubstantiated reports | B36: 2 | C36: Medium Risk
A37: Confirmed adverse media / regulatory action | B37: 4 | C37: Very High Risk
A42: 2.1 Country of Incorporation
A43: FATF member — low risk jurisdiction | B43: 1 | C43: Low Risk
A44: FATF member — standard / emerging jurisdiction | B44: 2 | C44: Medium Risk
A45: FATF Grey List country | B45: 3 | C45: High Risk
A46: FATF Black List / sanctioned country | B46: 4 | C46: Very High Risk
A50: 2.4 Countries of Operation
A51: All low-risk jurisdictions | B51: 1 | C51: Low Risk
A52: Predominantly low-risk with some medium-risk jurisdictions | B52: 2 | C52: Medium Risk
A53: Includes high-risk jurisdictions | B53: 3 | C53: High Risk
A54: Predominantly high-risk or sanctioned jurisdictions | B54: 4 | C54: Very High Risk
A58: 2.5 Target Markets / Payment Corridors
A59: Developed markets only | B59: 1 | C59: Low Risk
...

Sheet Country Risk Reference
A1: ARIE FINANCE LTD — COUNTRY RISK REFERENCE TABLE
A2: COUNTRY | B2: REGION | C2: FATF MEMBER | D2: FATF STATUS | E2: RISK SCORE | F2: RISK CATEGORY | G2: NOTES
A3: Australia | B3: Asia-Pacific | C3: Yes | D3: Clear | E3: 1 | F3: Low Risk | G3: FATF member; strong AML framework
A4: Canada | B4: Americas | C4: Yes | D4: Clear | E4: 1 | F4: Low Risk | G4: FATF member; strong AML framework
A5: France | B5: Europe | C5: Yes | D5: Clear | E5: 1 | F5: Low Risk | G5: FATF founding member
A6: Germany | B6: Europe | C6: Yes | D6: Clear | E6: 1 | F6: Low Risk | G6: FATF founding member
A7: Hong Kong SAR | B7: Asia-Pacific | C7: Yes | D7: Clear | E7: 1 | F7: Low Risk | G7: Strong regulatory framework
A8: Ireland | B8: Europe | C8: Yes | D8: Clear | E8: 1 | F8: Low Risk | G8: EU member; robust AML laws
A9: Japan | B9: Asia-Pacific | C9: Yes | D9: Clear | E9: 1 | F9: Low Risk | G9: FATF member; strong controls
A10: Luxembourg | B10: Europe | C10: Yes | D10: Clear | E10: 1 | F10: Low Risk | G10: EU financial centre
A11: Netherlands | B11: Europe | C11: Yes | D11: Clear | E11: 1 | F11: Low Risk | G11: FATF founding member
A12: New Zealand | B12: Asia-Pacific | C12: Yes | D12: Clear | E12: 1 | F12: Low Risk | G12: Strong AML/CFT framework
A13: Singapore | B13: Asia-Pacific | C13: Yes | D13: Clear | E13: 1 | F13: Low Risk | G13: MAS-regulated; highly compliant
A14: Switzerland | B14: Europe | C14: Yes | D14: Clear | E14: 1 | F14: Low Risk | G14: Strong FINMA-regulated framework
... A98: Iraq | B98: Middle East | C98: No | D98: Grey List | E98: 3 | F98: High Risk | G98: Conflict zone; sanctions exposure; weak AML. ADDED C-19.

Sheet Methodology
A1: ARIE FINANCE LTD — RISK SCORING MODEL: METHODOLOGY
A2: Version 1.6 — 26 March 2026 Change: Country Risk Reference expanded with 16 additional jurisdictions (BVI, Cayman Islands, Panama, Bermuda, Jersey, Guernsey, Isle of Man, Liechtenstein, Vanuatu, Samoa, Marshall Islands, Portugal, Italy, Estonia, Pakistan, Iraq). Seychelles reclassified from Medium to High Risk. Spain reclassified from Medium to Low Risk. Risk thresholds recalibrated to match normalised formula output range (0–100): Low 0–29, Medium 30–49, High 50–69, Very High 70–100. Previous thresholds (Low 0–39, Medium 40–54, High 55–69, Very High 70–100) were based on the Excel /4×100 formula; updated to align with code formula (x−1)/3×100. Version 1.5 — 17 March 2026 Change: Geographic Risk (Dimension 2) expanded from 3 to 5 sub-criteria. Added UBO Nationalities (20%) and Intermediary Shareholder Jurisdictions (20%) as new sub-factors. Rebalanced geographic sub-factor weights: Country of Incorporation 25%, UBO Nationalities 20%, Intermediary Shareholder Jurisdictions 20%, Countries of Operation 20%, Target Markets 15%. Updated VLOOKUP ranges and data validations. Entity types expanded in v1.4 (Trust, Foundation, Regulated Fund, Unregulated Fund/SPV split). Added Management Consulting and Financial/Tax Advisory sectors.
A4: PURPOSE
A5: This model provides a standardised, repeatable risk assessment framework for all corporate clients applying for Payment Intermediary Services (PIS) through ARIE Finance Ltd. It is designed to comply with the FATF Risk-Based Approach for banking and payment institutions.
A7: REGULATORY BASIS
A8: FATF Recommendations (2012, updated 2023) | FATF Risk-Based Approach Guidance: Banking Sector | FSC Mauritius AML/CFT Guidelines | Bank of Mauritius AML/CFT Guideline (2022)
A10: SCORING SCALE
A11: Each sub-factor is scored on a 1–4 scale: 1 = Low Risk 2 = Medium Risk 3 = High Risk 4 = Very High Risk
A13: DIMENSION WEIGHTS
A14: Dimension 1: Customer / Entity Risk — 30% Dimension 2: Geographic Risk — 25% • 2.1 Country of Incorporation (25%) • 2.2 UBO Nationalities (20%) • 2.3 Intermediary Shareholder Jurisdictions (20%) • 2.4 Countries of Operation (20%) • 2.5 Target Markets / Payment Corridors (15%) Dimension 3: Product / Service Risk — 20% Dimension 4: Industry / Sector Risk — 15% Dimension 5: Delivery Channel Risk — 10% Sub-factors 1.5 (Source of Wealth) and 1.6 (Initial Source of Funds) are included under Dimension 1 as customer-level risk indicators.
A16: COMPOSITE SCORE
A17: The weighted composite score is calculated as: Score = (Sum of all dimension weighted scores ÷ 4) × 100 This produces a normalised score from 0 to 100.
... A35: Version 1.5 — 17 March 2026 Change: Geographic Risk (Dimension 2) expanded from 3 to 5 sub-criteria. Added UBO Nationalities (20%) and Intermediary Shareholder Jurisdictions (20%) as new sub-factors. Rebalanced geographic sub-factor weights: Country of Incorporation 25%, UBO Nationalities 20%, Intermediary Shareholder Jurisdictions 20%, Countries of Operation 20%, Target Markets 15%. Updated VLOOKUP ranges and data validations. Entity types expanded in v1.4 (Trust, Foundation, Regulated Fund, Unregulated Fund/SPV split). Added Management Consulting and Financial/Tax Advisory sectors.
